<?xml version="1.0" ?>
<!-- =================================================================================== -->
<!-- |    This document was autogenerated by xacro from src/sinter_robot_mock/urdf/j2n6s300.urdf.xacro | -->
<!-- |    EDITING THIS FILE BY HAND IS NOT RECOMMENDED                                 | -->
<!-- =================================================================================== -->
<!--
  Top-level Kinova Jaco2 j2n6s300 URDF (with lens, no gripper).

  Xacro hierarchy:
    - package://sinter_arm_description/urdf/j2n6s300.urdf.xacro          (this file)
      - package://sinter_arm_description/urdf/j2n6s300_urdf_macro.xacro  (arm + lens macro)

  Usage:
    xacro j2n6s300.urdf.xacro
-->
<robot name="j2n6s300">
  <!--
    Kinova Jaco2 6DOF Non-Spherical (j2n6s300)
    6 DOF arm with 600x600x30mm lens payload (replaces gripper).

    Follows PickNik xacro naming conventions:
    - *_urdf_macro.xacro : macro definitions only, no output when included
    - *.urdf.xacro       : top-level file that calls macros

    Reference: https://docs.picknik.ai/how_to/configuration_tutorials/create_robot_mock_config/refactor_urdf_to_xacro/
  -->
  <link name="world"/>
  <!-- ========================================== -->
  <!--                 Base Link                  -->
  <!-- ========================================== -->
  <link name="j2n6s300_link_base">
    <visual>
      <geometry>
        <mesh filename="package://sinter_arm_description/meshes/visual/base.dae"/>
      </geometry>
      <material name="carbon_fiber">
        <color rgba="0.792 0.820 0.933 1"/>
      </material>
    </visual>
    <collision>
      <geometry>
        <mesh filename="package://sinter_arm_description/meshes/collision/base.STL"/>
      </geometry>
    </collision>
    <inertial>
      <mass value="0.46784"/>
      <origin rpy="0 0 0" xyz="0 0 0.1255"/>
      <inertia ixx="0.000951" ixy="0" ixz="0" iyy="0.000951" iyz="0" izz="0.000374"/>
    </inertial>
  </link>
  <joint name="j2n6s300_joint_base" type="fixed">
    <parent link="world"/>
    <child link="j2n6s300_link_base"/>
    <origin rpy="0 0 0" xyz="0 0 0"/>
  </joint>
  <!-- ========================================== -->
  <!--       Link 1 - Shoulder (continuous)       -->
  <!-- ========================================== -->
  <link name="j2n6s300_link_1">
    <visual>
      <geometry>
        <mesh filename="package://sinter_arm_description/meshes/visual/shoulder.dae"/>
      </geometry>
      <material name="carbon_fiber"/>
    </visual>
    <visual>
      <geometry>
        <mesh filename="package://sinter_arm_description/meshes/visual/ring_big.dae"/>
      </geometry>
    </visual>
    <collision>
      <geometry>
        <mesh filename="package://sinter_arm_description/meshes/collision/shoulder.STL"/>
      </geometry>
    </collision>
    <inertial>
      <mass value="0.7477"/>
      <origin xyz="0 -0.002 -0.0605"/>
      <inertia ixx="0.001520" ixy="0" ixz="0" iyy="0.001520" iyz="0" izz="0.000598"/>
    </inertial>
  </link>
  <joint name="j2n6s300_joint_1" type="continuous">
    <parent link="j2n6s300_link_base"/>
    <child link="j2n6s300_link_1"/>
    <axis xyz="0 0 1"/>
    <origin rpy="0 3.141592653589793 0" xyz="0 0 0.15675"/>
    <limit effort="40" velocity="0.6283185307179586"/>
    <dynamics damping="0.0" friction="0.0"/>
  </joint>
  <!-- ========================================== -->
  <!--          Link 2 - Arm (revolute)           -->
  <!-- ========================================== -->
  <link name="j2n6s300_link_2">
    <visual>
      <geometry>
        <mesh filename="package://sinter_arm_description/meshes/visual/arm.dae"/>
      </geometry>
      <material name="carbon_fiber"/>
    </visual>
    <visual>
      <geometry>
        <mesh filename="package://sinter_arm_description/meshes/visual/ring_big.dae"/>
      </geometry>
    </visual>
    <collision>
      <geometry>
        <mesh filename="package://sinter_arm_description/meshes/collision/arm.STL"/>
      </geometry>
    </collision>
    <inertial>
      <mass value="0.99"/>
      <origin xyz="0 -0.2065 -0.01"/>
      <inertia ixx="0.010503" ixy="0" ixz="0" iyy="0.000792" iyz="0" izz="0.010503"/>
    </inertial>
  </link>
  <joint name="j2n6s300_joint_2" type="revolute">
    <parent link="j2n6s300_link_1"/>
    <child link="j2n6s300_link_2"/>
    <axis xyz="0 0 1"/>
    <origin rpy="-1.5707963267948966 0 3.141592653589793" xyz="0 0.0016 -0.11875"/>
    <limit effort="80" lower="0.8203047484373349" upper="5.462880558742251" velocity="0.6283185307179586"/>
    <dynamics damping="0.0" friction="0.0"/>
  </joint>
  <!-- ========================================== -->
  <!--        Link 3 - Forearm (revolute)         -->
  <!-- ========================================== -->
  <link name="j2n6s300_link_3">
    <visual>
      <geometry>
        <mesh filename="package://sinter_arm_description/meshes/visual/forearm.dae"/>
      </geometry>
      <material name="carbon_fiber"/>
    </visual>
    <visual>
      <geometry>
        <mesh filename="package://sinter_arm_description/meshes/visual/ring_big.dae"/>
      </geometry>
    </visual>
    <collision>
      <geometry>
        <mesh filename="package://sinter_arm_description/meshes/collision/forearm.STL"/>
      </geometry>
    </collision>
    <inertial>
      <mass value="0.6763"/>
      <origin xyz="0 0.081 -0.0086"/>
      <inertia ixx="0.001420" ixy="0" ixz="0" iyy="0.000304" iyz="0" izz="0.001420"/>
    </inertial>
  </link>
  <joint name="j2n6s300_joint_3" type="revolute">
    <parent link="j2n6s300_link_2"/>
    <child link="j2n6s300_link_3"/>
    <axis xyz="0 0 1"/>
    <origin rpy="0 3.141592653589793 0" xyz="0 -0.410 0"/>
    <limit effort="40" lower="0.3316125578789226" upper="5.951572749300663" velocity="0.6283185307179586"/>
    <dynamics damping="0.0" friction="0.0"/>
  </joint>
  <!-- ========================================== -->
  <!--      Link 4 - Wrist 1 (continuous)         -->
  <!-- ========================================== -->
  <link name="j2n6s300_link_4">
    <visual>
      <geometry>
        <mesh filename="package://sinter_arm_description/meshes/visual/wrist.dae"/>
      </geometry>
      <material name="carbon_fiber"/>
    </visual>
    <visual>
      <geometry>
        <mesh filename="package://sinter_arm_description/meshes/visual/ring_small.dae"/>
      </geometry>
    </visual>
    <collision>
      <geometry>
        <mesh filename="package://sinter_arm_description/meshes/collision/wrist.STL"/>
      </geometry>
    </collision>
    <inertial>
      <mass value="0.426367"/>
      <origin xyz="0 -0.037 -0.0642"/>
      <inertia ixx="0.000077" ixy="0" ixz="0" iyy="0.000077" iyz="0" izz="0.000143"/>
    </inertial>
  </link>
  <joint name="j2n6s300_joint_4" type="continuous">
    <parent link="j2n6s300_link_3"/>
    <child link="j2n6s300_link_4"/>
    <axis xyz="0 0 1"/>
    <origin rpy="-1.5707963267948966 0 3.141592653589793" xyz="0 0.2073 -0.0114"/>
    <limit effort="20" velocity="0.8377580409572781"/>
    <dynamics damping="0.0" friction="0.0"/>
  </joint>
  <!-- ========================================== -->
  <!--      Link 5 - Wrist 2 (continuous)         -->
  <!-- ========================================== -->
  <link name="j2n6s300_link_5">
    <visual>
      <geometry>
        <mesh filename="package://sinter_arm_description/meshes/visual/wrist.dae"/>
      </geometry>
      <material name="carbon_fiber"/>
    </visual>
    <visual>
      <geometry>
        <mesh filename="package://sinter_arm_description/meshes/visual/ring_small.dae"/>
      </geometry>
    </visual>
    <collision>
      <geometry>
        <mesh filename="package://sinter_arm_description/meshes/collision/wrist.STL"/>
      </geometry>
    </collision>
    <inertial>
      <mass value="0.426367"/>
      <origin xyz="0 -0.037 -0.0642"/>
      <inertia ixx="0.000077" ixy="0" ixz="0" iyy="0.000077" iyz="0" izz="0.000143"/>
    </inertial>
  </link>
  <joint name="j2n6s300_joint_5" type="continuous">
    <parent link="j2n6s300_link_4"/>
    <child link="j2n6s300_link_5"/>
    <axis xyz="0 0 1"/>
    <origin rpy="1.0471975511965976 0 3.141592653589793" xyz="0 -0.03703 -0.06414"/>
    <limit effort="20" velocity="0.8377580409572781"/>
    <dynamics damping="0.0" friction="0.0"/>
  </joint>
  <!-- ========================================== -->
  <!--    Link 6 - End Cap / Mount (continuous)   -->
  <!-- ========================================== -->
  <!-- Link 6 is a virtual mount point: gripper/end effector removed, lens attaches here -->
  <link name="j2n6s300_link_6">
    <inertial>
      <mass value="0.99"/>
      <origin xyz="0 0 -0.06"/>
      <inertia ixx="0.000345" ixy="0" ixz="0" iyy="0.000345" iyz="0" izz="0.000582"/>
    </inertial>
  </link>
  <joint name="j2n6s300_joint_6" type="continuous">
    <parent link="j2n6s300_link_5"/>
    <child link="j2n6s300_link_6"/>
    <axis xyz="0 0 1"/>
    <origin rpy="1.0471975511965976 0 3.141592653589793" xyz="0 -0.03703 -0.06414"/>
    <limit effort="20" velocity="0.8377580409572781"/>
    <dynamics damping="0.0" friction="0.0"/>
  </joint>
  <!-- ========================================== -->
  <!--        Lens Payload (600x600x30mm)         -->
  <!--   Fixed to link_6, replaces gripper        -->
  <!-- ========================================== -->
  <link name="j2n6s300_lens">
    <visual>
      <origin rpy="0 0 0" xyz="0 0 0"/>
      <geometry>
        <box size="0.6 0.6 0.03"/>
      </geometry>
      <material name="lens_glass">
        <color rgba="0.3 0.3 0.8 0.5"/>
      </material>
    </visual>
    <collision>
      <origin rpy="0 0 0" xyz="0 0 0"/>
      <geometry>
        <box size="0.6 0.6 0.03"/>
      </geometry>
    </collision>
    <inertial>
      <mass value="5.0"/>
      <origin xyz="0 0 0"/>
      <inertia ixx="0.150375" ixy="0" ixz="0" iyy="0.150375" iyz="0" izz="0.300000"/>
    </inertial>
  </link>
  <joint name="j2n6s300_lens_joint" type="fixed">
    <parent link="j2n6s300_link_6"/>
    <child link="j2n6s300_lens"/>
    <origin rpy="0 1.5707963267948966 0" xyz="0 0 -0.3"/>
  </joint>
  <ros2_control name="j2n6s300" type="system">
    <joint name="j2n6s300_joint_1">
      <command_interface name="velocity"/>
      <state_interface name="position"/>
      <state_interface name="velocity"/>
      <state_interface name="effort"/>
    </joint>
    <joint name="j2n6s300_joint_2">
      <command_interface name="velocity"/>
      <state_interface name="position"/>
      <state_interface name="velocity"/>
      <state_interface name="effort"/>
    </joint>
    <joint name="j2n6s300_joint_3">
      <command_interface name="velocity"/>
      <state_interface name="position"/>
      <state_interface name="velocity"/>
      <state_interface name="effort"/>
    </joint>
    <joint name="j2n6s300_joint_4">
      <command_interface name="velocity"/>
      <state_interface name="position"/>
      <state_interface name="velocity"/>
      <state_interface name="effort"/>
    </joint>
    <joint name="j2n6s300_joint_5">
      <command_interface name="velocity"/>
      <state_interface name="position"/>
      <state_interface name="velocity"/>
      <state_interface name="effort"/>
    </joint>
    <joint name="j2n6s300_joint_6">
      <command_interface name="velocity"/>
      <state_interface name="position"/>
      <state_interface name="velocity"/>
      <state_interface name="effort"/>
    </joint>
    <hardware>
      <plugin>mock_components/GenericSystem</plugin>
      <param name="state_following_offset">0.0</param>
      <param name="calculate_dynamics">true</param>
    </hardware>
  </ros2_control>
</robot>
